Workbook

Sheet Sales Data
A1: MINI-MART SALES RECORDS - Q1 2026
A2: Fill in the yellow columns using the functions listed on the 'Assignment Questions' sheet.
A4: Order ID | B4: Date | C4: Salesperson | D4: Region | E4: Product Code | F4: Units Sold | G4: Customer Type | H4: Payment Method | I4: Product Name | J4: Category | K4: Unit Price (N) | L4: Total Sales (N) | M4: Sales Rating
A5: ORD1000 | B5: 46108 | C5: Tunde Bakare | D5: Lagos | E5: P005 | F5: 17 | G5: New | H5: Transfer | I5: =VLOOKUP(E5,'Product List'!$A$4:$D$14,2,FALSE) -> Powdered Milk (Carton) | J5: =VLOOKUP(E5,'Product List'!$A$2:$D$100,3,FALSE) -> Dairy | K5: =VLOOKUP(E5,'Product List'!$A$2:$D$100,4,FALSE) -> 32000 | L5: =F5*K5 -> 544000 | M5: =IF(L5<500000,"Low",IF(L5<1000000,"Medium",IF(L5<2000000,"High","Excellent"))) -> Medium
A6: ORD1001 | B6: 46040 | C6: Tunde Bakare | D6: Ibadan | E6: P007 | F6: 4 | G6: New | H6: Cash | I6: =VLOOKUP(E6,'Product List'!$A$4:$D$14,2,FALSE) -> Table Salt (Carton) | J6: =VLOOKUP(E6,'Product List'!$A$2:$D$100,3,FALSE) -> Cooking Essentials | K6: =VLOOKUP(E6,'Product List'!$A$2:$D$100,4,FALSE) -> 8500 | L6: =F6*K6 -> 34000 | M6: =IF(L6<500000,"Low",IF(L6<1000000,"Medium",IF(L6<2000000,"High","Excellent"))) -> Low
A7: ORD1002 | B7: 46056 | C7: Adaeze Obi | D7: Ibadan | E7: P004 | F7: 47 | G7: Returning | H7: Transfer | I7: =VLOOKUP(E7,'Product List'!$A$4:$D$14,2,FALSE) -> Granulated Sugar (50kg) | J7: =VLOOKUP(E7,'Product List'!$A$2:$D$100,3,FALSE) -> Cooking Essentials | K7: =VLOOKUP(E7,'Product List'!$A$2:$D$100,4,FALSE) -> 58000 | L7: =F7*K7 -> 2726000 | M7: =IF(L7<500000,"Low",IF(L7<1000000,"Medium",IF(L7<2000000,"High","Excellent"))) -> Excellent
A8: ORD1003 | B8: 46080 | C8: Ibrahim Musa | D8: Port Harcourt | E8: P010 | F8: 19 | G8: Returning | H8: Cash | I8: =VLOOKUP(E8,'Product List'!$A$4:$D$14,2,FALSE) -> Bathing Soap (Carton) | J8: =VLOOKUP(E8,'Product List'!$A$2:$D$100,3,FALSE) -> Household | K8: =VLOOKUP(E8,'Product List'!$A$2:$D$100,4,FALSE) -> 15500 | L8: =F8*K8 -> 294500 | M8: =IF(L8<500000,"Low",IF(L8<1000000,"Medium",IF(L8<2000000,"High","Excellent"))) -> Low
A9: ORD1004 | B9: 46047 | C9: Sadiq Bello | D9: Kano | E9: P005 | F9: 11 | G9: New | H9: Card | I9: =VLOOKUP(E9,'Product List'!$A$4:$D$14,2,FALSE) -> Powdered Milk (Carton) | J9: =VLOOKUP(E9,'Product List'!$A$2:$D$100,3,FALSE) -> Dairy | K9: =VLOOKUP(E9,'Product List'!$A$2:$D$100,4,FALSE) -> 32000 | L9: =F9*K9 -> 352000 | M9: =IF(L9<500000,"Low",IF(L9<1000000,"Medium",IF(L9<2000000,"High","Excellent"))) -> Low
A10: ORD1005 | B10: 46040 | C10: Tunde Bakare | D10: Port Harcourt | E10: P002 | F10: 24 | G10: Returning | H10: Transfer | I10: =VLOOKUP(E10,'Product List'!$A$4:$D$14,2,FALSE) -> Beans (50kg bag) | J10: =VLOOKUP(E10,'Product List'!$A$2:$D$100,3,FALSE) -> Grains | K10: =VLOOKUP(E10,'Product List'!$A$2:$D$100,4,FALSE) -> 62000 | L10: =F10*K10 -> 1488000 | M10: =IF(L10<500000,"Low",IF(L10<1000000,"Medium",IF(L10<2000000,"High","Excellent"))) -> High
A11: ORD1006 | B11: 46060 | C11: Adaeze Obi | D11: Port Harcourt | E11: P009 | F11: 9 | G11: Returning | H11: Card | I11: =VLOOKUP(E11,'Product List'!$A$4:$D$14,2,FALSE) -> Laundry Detergent (Carton) | J11: =VLOOKUP(E11,'Product List'!$A$2:$D$100,3,FALSE) -> Household | K11: =VLOOKUP(E11,'Product List'!$A$2:$D$100,4,FALSE) -> 21000 | L11: =F11*K11 -> 189000 | M11: =IF(L11<500000,"Low",IF(L11<1000000,"Medium",IF(L11<2000000,"High","Excellent"))) -> Low
A12: ORD1007 | B12: 46037 | C12: Femi Alabi | D12: Ibadan | E12: P006 | F12: 38 | G12: New | H12: Cash | I12: =VLOOKUP(E12,'Product List'!$A$4:$D$14,2,FALSE) -> Wheat Flour (50kg) | J12: =VLOOKUP(E12,'Product List'!$A$2:$D$100,3,FALSE) -> Grains | K12: =VLOOKUP(E12,'Product List'!$A$2:$D$100,4,FALSE) -> 41000 | L12: =F12*K12 -> 1558000 | M12: =IF(L12<500000,"Low",IF(L12<1000000,"Medium",IF(L12<2000000,"High","Excellent"))) -> High
A13: ORD1008 | B13: 46032 | C13: Ibrahim Musa | D13: Kano | E13: P002 | F13: 56 | G13: New | H13: Cash | I13: =VLOOKUP(E13,'Product List'!$A$4:$D$14,2,FALSE) -> Beans (50kg bag) | J13: =VLOOKUP(E13,'Product List'!$A$2:$D$100,3,FALSE) -> Grains | K13: =VLOOKUP(E13,'Product List'!$A$2:$D$100,4,FALSE) -> 62000 | L13: =F13*K13 -> 3472000 | M13: =IF(L13<500000,"Low",IF(L13<1000000,"Medium",IF(L13<2000000,"High","Excellent"))) -> Excellent
A14: ORD1009 | B14: 46075 | C14: Femi Alabi | D14: Port Harcourt | E14: P006 | F14: 12 | G14: New | H14: Cash | I14: =VLOOKUP(E14,'Product List'!$A$4:$D$14,2,FALSE) -> Wheat Flour (50kg) | J14: =VLOOKUP(E14,'Product List'!$A$2:$D$100,3,FALSE) -> Grains | K14: =VLOOKUP(E14,'Product List'!$A$2:$D$100,4,FALSE) -> 41000 | L14: =F14*K14 -> 492000 | M14: =IF(L14<500000,"Low",IF(L14<1000000,"Medium",IF(L14<2000000,"High","Excellent"))) -> Low
A15: ORD1010 | B15: 46061 | C15: Tunde Bakare | D15: Ibadan | E15: P003 | F15: 36 | G15: Returning | H15: Cash | I15: =VLOOKUP(E15,'Product List'!$A$4:$D$14,2,FALSE) -> Vegetable Oil (25L) | J15: =VLOOKUP(E15,'Product List'!$A$2:$D$100,3,FALSE) -> Cooking Essentials | K15: =VLOOKUP(E15,'Product List'!$A$2:$D$100,4,FALSE) -> 45000 | L15: =F15*K15 -> 1620000 | M15: =IF(L15<500000,"Low",IF(L15<1000000,"Medium",IF(L15<2000000,"High","Excellent"))) -> High
A16: ORD1011 | B16: 46086 | C16: Sadiq Bello | D16: Kano | E16: P009 | F16: 16 | G16: Returning | H16: Cash | I16: =VLOOKUP(E16,'Product List'!$A$4:$D$14,2,FALSE) -> Laundry Detergent (Carton) | J16: =VLOOKUP(E16,'Product List'!$A$2:$D$100,3,FALSE) -> Household | K16: =VLOOKUP(E16,'Product List'!$A$2:$D$100,4,FALSE) -> 21000 | L16: =F16*K16 -> 336000 | M16: =IF(L16<500000,"Low",IF(L16<1000000,"Medium",IF(L16<2000000,"High","Excellent"))) -> Low
... A30: ORD1025 | B30: 46104 | C30: Sadiq Bello | D30: Abuja | E30: P009 | F30: 50 | G30: Returning | H30: Cash | I30: =VLOOKUP(E30,'Product List'!$A$4:$D$14,2,FALSE) -> Laundry Detergent (Carton) | J30: =VLOOKUP(E30,'Product List'!$A$2:$D$100,3,FALSE) -> Household | K30: =VLOOKUP(E30,'Product List'!$A$2:$D$100,4,FALSE) -> 21000 | L30: =F30*K30 -> 1050000 | M30: =IF(L30<500000,"Low",IF(L30<1000000,"Medium",IF(L30<2000000,"High","Excellent"))) -> High
A31: ORD1026 | B31: 46066 | C31: Sadiq Bello | D31: Kano | E31: P008 | F31: 59 | G31: Returning | H31: Cash | I31: =VLOOKUP(E31,'Product List'!$A$4:$D$14,2,FALSE) -> Instant Noodles (Carton) | J31: =VLOOKUP(E31,'Product List'!$A$2:$D$100,3,FALSE) -> Packaged Foods | K31: =VLOOKUP(E31,'Product List'!$A$2:$D$100,4,FALSE) -> 12500 | L31: =F31*K31 -> 737500 | M31: =IF(L5<500000,"Low",IF(L5<1000000,"Medium",IF(L5<2000000,"High","Excellent"))) -> Medium
A32: ORD1027 | B32: 46058 | C32: Ibrahim Musa | D32: Lagos | E32: P006 | F32: 3 | G32: Returning | H32: Cash | I32: =VLOOKUP(E32,'Product List'!$A$4:$D$14,2,FALSE) -> Wheat Flour (50kg) | J32: =VLOOKUP(E32,'Product List'!$A$2:$D$100,3,FALSE) -> Grains | K32: =VLOOKUP(E32,'Product List'!$A$2:$D$100,4,FALSE) -> 41000 | L32: =F32*K32 -> 123000 | M32: =IF(L6<500000,"Low",IF(L6<1000000,"Medium",IF(L6<2000000,"High","Excellent"))) -> Low
A33: ORD1028 | B33: 46102 | C33: Ibrahim Musa | D33: Lagos | E33: P002 | F33: 47 | G33: Returning | H33: Cash | I33: =VLOOKUP(E33,'Product List'!$A$4:$D$14,2,FALSE) -> Beans (50kg bag) | J33: =VLOOKUP(E33,'Product List'!$A$2:$D$100,3,FALSE) -> Grains | K33: =VLOOKUP(E33,'Product List'!$A$2:$D$100,4,FALSE) -> 62000 | L33: =F33*K33 -> 2914000 | M33: =IF(L7<500000,"Low",IF(L7<1000000,"Medium",IF(L7<2000000,"High","Excellent"))) -> Excellent
A34: ORD1029 | B34: 46035 | C34: Adaeze Obi | D34: Kano | E34: P002 | F34: 34 | G34: New | H34: Transfer | I34: =VLOOKUP(E34,'Product List'!$A$4:$D$14,2,FALSE) -> Beans (50kg bag) | J34: =VLOOKUP(E34,'Product List'!$A$2:$D$100,3,FALSE) -> Grains | K34: =VLOOKUP(E34,'Product List'!$A$2:$D$100,4,FALSE) -> 62000 | L34: =F34*K34 -> 2108000 | M34: =IF(L8<500000,"Low",IF(L8<1000000,"Medium",IF(L8<2000000,"High","Excellent"))) -> Low
A35: ORD1030 | B35: 46089 | C35: Ibrahim Musa | D35: Ibadan | E35: P003 | F35: 48 | G35: Returning | H35: Transfer | I35: =VLOOKUP(E35,'Product List'!$A$4:$D$14,2,FALSE) -> Vegetable Oil (25L) | J35: =VLOOKUP(E35,'Product List'!$A$2:$D$100,3,FALSE) -> Cooking Essentials | K35: =VLOOKUP(E35,'Product List'!$A$2:$D$100,4,FALSE) -> 45000 | L35: =F35*K35 -> 2160000 | M35: =IF(L9<500000,"Low",IF(L9<1000000,"Medium",IF(L9<2000000,"High","Excellent"))) -> Low | N35: Lagos Total Sales
A36: ORD1031 | B36: 46100 | C36: Kemi Adisa | D36: Abuja | E36: P008 | F36: 53 | G36: New | H36: Cash | I36: =VLOOKUP(E36,'Product List'!$A$4:$D$14,2,FALSE) -> Instant Noodles (Carton) | J36: =VLOOKUP(E36,'Product List'!$A$2:$D$100,3,FALSE) -> Packaged Foods | K36: =VLOOKUP(E36,'Product List'!$A$2:$D$100,4,FALSE) -> 12500 | L36: =F36*K36 -> 662500 | M36: =IF(L10<500000,"Low",IF(L10<1000000,"Medium",IF(L10<2000000,"High","Excellent"))) -> High | N36: =SUMIF(D5:D64,"Lagos",L5:L64) -> 10016000
A37: ORD1032 | B37: 46039 | C37: Sadiq Bello | D37: Kano | E37: P007 | F37: 28 | G37: Returning | H37: Transfer | I37: =VLOOKUP(E37,'Product List'!$A$4:$D$14,2,FALSE) -> Table Salt (Carton) | J37: =VLOOKUP(E37,'Product List'!$A$2:$D$100,3,FALSE) -> Cooking Essentials | K37: =VLOOKUP(E37,'Product List'!$A$2:$D$100,4,FALSE) -> 8500 | L37: =F37*K37 -> 238000 | M37: =IF(L11<500000,"Low",IF(L11<1000000,"Medium",IF(L11<2000000,"High","Excellent"))) -> Low
A38: ORD1033 | B38: 46033 | C38: Tunde Bakare | D38: Lagos | E38: P007 | F38: 48 | G38: New | H38: Cash | I38: =VLOOKUP(E38,'Product List'!$A$4:$D$14,2,FALSE) -> Table Salt (Carton) | J38: =VLOOKUP(E38,'Product List'!$A$2:$D$100,3,FALSE) -> Cooking Essentials | K38: =VLOOKUP(E38,'Product List'!$A$2:$D$100,4,FALSE) -> 8500 | L38: =F38*K38 -> 408000 | M38: =IF(L12<500000,"Low",IF(L12<1000000,"Medium",IF(L12<2000000,"High","Excellent"))) -> High
A39: ORD1034 | B39: 46058 | C39: Ibrahim Musa | D39: Abuja | E39: P009 | F39: 30 | G39: New | H39: Cash | I39: =VLOOKUP(E39,'Product List'!$A$4:$D$14,2,FALSE) -> Laundry Detergent (Carton) | J39: =VLOOKUP(E39,'Product List'!$A$2:$D$100,3,FALSE) -> Household | K39: =VLOOKUP(E39,'Product List'!$A$2:$D$100,4,FALSE) -> 21000 | L39: =F39*K39 -> 630000 | M39: =IF(L13<500000,"Low",IF(L13<1000000,"Medium",IF(L13<2000000,"High","Excellent"))) -> Excellent
A40: ORD1035 | B40: 46062 | C40: Kemi Adisa | D40: Abuja | E40: P002 | F40: 30 | G40: Returning | H40: Transfer | I40: =VLOOKUP(E40,'Product List'!$A$4:$D$14,2,FALSE) -> Beans (50kg bag) | J40: =VLOOKUP(E40,'Product List'!$A$2:$D$100,3,FALSE) -> Grains | K40: =VLOOKUP(E40,'Product List'!$A$2:$D$100,4,FALSE) -> 62000 | L40: =F40*K40 -> 1860000 | M40: =IF(L14<500000,"Low",IF(L14<1000000,"Medium",IF(L14<2000000,"High","Excellent"))) -> Low | N40: Tunde Bakare Total Unit Sold
A41: ORD1036 | B41: 46039 | C41: Adaeze Obi | D41: Ibadan | E41: P001 | F41: 7 | G41: Returning | H41: Cash | I41: =VLOOKUP(E41,'Product List'!$A$4:$D$14,2,FALSE) -> Rice (50kg bag) | J41: =VLOOKUP(E41,'Product List'!$A$2:$D$100,3,FALSE) -> Grains | K41: =VLOOKUP(E41,'Product List'!$A$2:$D$100,4,FALSE) -> 68000 | L41: =F41*K41 -> 476000 | M41: =IF(L15<500000,"Low",IF(L15<1000000,"Medium",IF(L15<2000000,"High","Excellent"))) -> High | N41: =SUMIF(C5:C64,"Tunde Bakare",F5:F64) -> 185
A42: ORD1037 | B42: 46048 | C42: Sadiq Bello | D42: Port Harcourt | E42: P008 | F42: 15 | G42: Returning | H42: Cash | I42: =VLOOKUP(E42,'Product List'!$A$4:$D$14,2,FALSE) -> Instant Noodles (Carton) | J42: =VLOOKUP(E42,'Product List'!$A$2:$D$100,3,FALSE) -> Packaged Foods | K42: =VLOOKUP(E42,'Product List'!$A$2:$D$100,4,FALSE) -> 12500 | L42: =F42*K42 -> 187500 | M42: =IF(L16<500000,"Low",IF(L16<1000000,"Medium",IF(L16<2000000,"High","Excellent"))) -> Low
A43: ORD1038 | B43: 46048 | C43: Sadiq Bello | D43: Lagos | E43: P007 | F43: 18 | G43: Returning | H43: Card | I43: =VLOOKUP(E43,'Product List'!$A$4:$D$14,2,FALSE) -> Table Salt (Carton) | J43: =VLOOKUP(E43,'Product List'!$A$2:$D$100,3,FALSE) -> Cooking Essentials | K43: =VLOOKUP(E43,'Product List'!$A$2:$D$100,4,FALSE) -> 8500 | L43: =F43*K43 -> 153000 | M43: =IF(L17<500000,"Low",IF(L17<1000000,"Medium",IF(L17<2000000,"High","Excellent"))) -> Low
A44: ORD1039 | B44: 46063 | C44: Sadiq Bello | D44: Ibadan | E44: P008 | F44: 11 | G44: New | H44: Cash | I44: =VLOOKUP(E44,'Product List'!$A$4:$D$14,2,FALSE) -> Instant Noodles (Carton) | J44: =VLOOKUP(E44,'Product List'!$A$2:$D$100,3,FALSE) -> Packaged Foods | K44: =VLOOKUP(E44,'Product List'!$A$2:$D$100,4,FALSE) -> 12500 | L44: =F44*K44 -> 137500 | M44: =IF(L18<500000,"Low",IF(L18<1000000,"Medium",IF(L18<2000000,"High","Excellent"))) -> Low
A45: ORD1040 | B45: 46034 | C45: Adaeze Obi | D45: Kano | E45: P001 | F45: 5 | G45: Returning | H45: Transfer | I45: =VLOOKUP(E45,'Product List'!$A$4:$D$14,2,FALSE) -> Rice (50kg bag) | J45: =VLOOKUP(E45,'Product List'!$A$2:$D$100,3,FALSE) -> Grains | K45: =VLOOKUP(E45,'Product List'!$A$2:$D$100,4,FALSE) -> 68000 | L45: =F45*K45 -> 340000 | M45: =IF(L19<500000,"Low",IF(L19<1000000,"Medium",IF(L19<2000000,"High","Excellent"))) -> Excellent | N45: Count Transfer Payments
A46: ORD1041 | B46: 46094 | C46: Chinwe Eze | D46: Lagos | E46: P009 | F46: 7 | G46: Returning | H46: Cash | I46: =VLOOKUP(E46,'Product List'!$A$4:$D$14,2,FALSE) -> Laundry Detergent (Carton) | J46: =VLOOKUP(E46,'Product List'!$A$2:$D$100,3,FALSE) -> Household | K46: =VLOOKUP(E46,'Product List'!$A$2:$D$100,4,FALSE) -> 21000 | L46: =F46*K46 -> 147000 | M46: =IF(L20<500000,"Low",IF(L20<1000000,"Medium",IF(L20<2000000,"High","Excellent"))) -> Low | N46: =COUNTIF(H5:H64,"Transfer") -> 19
A47: ORD1042 | B47: 46103 | C47: Tunde Bakare | D47: Abuja | E47: P007 | F47: 9 | G47: Returning | H47: Transfer | I47: =VLOOKUP(E47,'Product List'!$A$4:$D$14,2,FALSE) -> Table Salt (Carton) | J47: =VLOOKUP(E47,'Product List'!$A$2:$D$100,3,FALSE) -> Cooking Essentials | K47: =VLOOKUP(E47,'Product List'!$A$2:$D$100,4,FALSE) -> 8500 | L47: =F47*K47 -> 76500 | M47: =IF(L21<500000,"Low",IF(L21<1000000,"Medium",IF(L21<2000000,"High","Excellent"))) -> Excellent
A48: ORD1043 | B48: 46058 | C48: Adaeze Obi | D48: Ibadan | E48: P002 | F48: 28 | G48: Returning | H48: Transfer | I48: =VLOOKUP(E48,'Product List'!$A$4:$D$14,2,FALSE) -> Beans (50kg bag) | J48: =VLOOKUP(E48,'Product List'!$A$2:$D$100,3,FALSE) -> Grains | K48: =VLOOKUP(E48,'Product List'!$A$2:$D$100,4,FALSE) -> 62000 | L48: =F48*K48 -> 1736000 | M48: =IF(L22<500000,"Low",IF(L22<1000000,"Medium",IF(L22<2000000,"High","Excellent"))) -> High
A49: ORD1044 | B49: 46093 | C49: Ngozi Umeh | D49: Kano | E49: P004 | F49: 44 | G49: Returning | H49: Cash | I49: =VLOOKUP(E49,'Product List'!$A$4:$D$14,2,FALSE) -> Granulated Sugar (50kg) | J49: =VLOOKUP(E49,'Product List'!$A$2:$D$100,3,FALSE) -> Cooking Essentials | K49: =VLOOKUP(E49,'Product List'!$A$2:$D$100,4,FALSE) -> 58000 | L49: =F49*K49 -> 2552000 | M49: =IF(L23<500000,"Low",IF(L23<1000000,"Medium",IF(L23<2000000,"High","Excellent"))) -> Excellent
A50: ORD1045 | B50: 46060 | C50: Sadiq Bello | D50: Abuja | E50: P005 | F50: 31 | G50: New | H50: Cash | I50: =VLOOKUP(E50,'Product List'!$A$4:$D$14,2,FALSE) -> Powdered Milk (Carton) | J50: =VLOOKUP(E50,'Product List'!$A$2:$D$100,3,FALSE) -> Dairy | K50: =VLOOKUP(E50,'Product List'!$A$2:$D$100,4,FALSE) -> 32000 | L50: =F50*K50 -> 992000 | M50: =IF(L24<500000,"Low",IF(L24<1000000,"Medium",IF(L24<2000000,"High","Excellent"))) -> High | N50: Abuja + Card Total Sales
A51: ORD1046 | B51: 46028 | C51: Kemi Adisa | D51: Ibadan | E51: P010 | F51: 8 | G51: New | H51: Cash | I51: =VLOOKUP(E51,'Product List'!$A$4:$D$14,2,FALSE) -> Bathing Soap (Carton) | J51: =VLOOKUP(E51,'Product List'!$A$2:$D$100,3,FALSE) -> Household | K51: =VLOOKUP(E51,'Product List'!$A$2:$D$100,4,FALSE) -> 15500 | L51: =F51*K51 -> 124000 | M51: =IF(L25<500000,"Low",IF(L25<1000000,"Medium",IF(L25<2000000,"High","Excellent"))) -> High | N51: =SUMIFS(L5:L64,D5:D64,"Abuja",H5:H64,"Card") -> 9123000
A52: ORD1047 | B52: 46091 | C52: Femi Alabi | D52: Abuja | E52: P006 | F52: 58 | G52: New | H52: Cash | I52: =VLOOKUP(E52,'Product List'!$A$4:$D$14,2,FALSE) -> Wheat Flour (50kg) | J52: =VLOOKUP(E52,'Product List'!$A$2:$D$100,3,FALSE) -> Grains | K52: =VLOOKUP(E52,'Product List'!$A$2:$D$100,4,FALSE) -> 41000 | L52: =F52*K52 -> 2378000 | M52: =IF(L26<500000,"Low",IF(L26<1000000,"Medium",IF(L26<2000000,"High","Excellent"))) -> Excellent
A53: ORD1048 | B53: 46074 | C53: Femi Alabi | D53: Abuja | E53: P008 | F53: 55 | G53: Returning | H53: Card | I53: =VLOOKUP(E53,'Product List'!$A$4:$D$14,2,FALSE) -> Instant Noodles (Carton) | J53: =VLOOKUP(E53,'Product List'!$A$2:$D$100,3,FALSE) -> Packaged Foods | K53: =VLOOKUP(E53,'Product List'!$A$2:$D$100,4,FALSE) -> 12500 | L53: =F53*K53 -> 687500 | M53: =IF(L27<500000,"Low",IF(L27<1000000,"Medium",IF(L27<2000000,"High","Excellent"))) -> Medium
A54: ORD1049 | B54: 46105 | C54: Adaeze Obi | D54: Ibadan | E54: P005 | F54: 44 | G54: New | H54: Cash | I54: =VLOOKUP(E54,'Product List'!$A$4:$D$14,2,FALSE) -> Powdered Milk (Carton) | J54: =VLOOKUP(E54,'Product List'!$A$2:$D$100,3,FALSE) -> Dairy | K54: =VLOOKUP(E54,'Product List'!$A$2:$D$100,4,FALSE) -> 32000 | L54: =F54*K54 -> 1408000 | M54: =IF(L28<500000,"Low",IF(L28<1000000,"Medium",IF(L28<2000000,"High","Excellent"))) -> Low
...

Sheet Product List
A1: PRODUCT PRICE LIST
A2: Use this table as the lookup range for VLOOKUP. Consider naming this range.
A4: Product Code | B4: Product Name | C4: Category | D4: Unit Price (N)
A5: P001 | B5: Rice (50kg bag) | C5: Grains | D5: 68000
A6: P002 | B6: Beans (50kg bag) | C6: Grains | D6: 62000
A7: P003 | B7: Vegetable Oil (25L) | C7: Cooking Essentials | D7: 45000
A8: P004 | B8: Granulated Sugar (50kg) | C8: Cooking Essentials | D8: 58000
A9: P005 | B9: Powdered Milk (Carton) | C9: Dairy | D9: 32000
A10: P006 | B10: Wheat Flour (50kg) | C10: Grains | D10: 41000
A11: P007 | B11: Table Salt (Carton) | C11: Cooking Essentials | D11: 8500
A12: P008 | B12: Instant Noodles (Carton) | C12: Packaged Foods | D12: 12500
A13: P009 | B13: Laundry Detergent (Carton) | C13: Household | D13: 21000
A14: P010 | B14: Bathing Soap (Carton) | C14: Household | D14: 15500
A17: SALES RATING GUIDE
A18: Total Sales (N) | B18: Rating
A19: Less than 500,000 | B19: Low
A20: 500,000 - 999,999 | B20: Medium
A21: 1,000,000 - 1,999,999 | B21: High
A22: 2,000,000 and above | B22: Excellent

Sheet Assignment Questions
A1: EXCEL ASSIGNMENT - SALES DATA ANALYSIS
A2: Use the 'Sales Data' and 'Product List' sheets to answer the questions below.
A4: No. | B4: Question | C4: Topic | D4: Your Answer
A5: 1 | B5: On the 'Sales Data' sheet, use the Product Code (column E) to look up and fill in the Product Name, Category, and Unit Price for every order, using the Product List sheet as your lookup table. | C5: VLOOKUP
A6: 2 | B6: Calculate the Total Sales (N) for every order as Units Sold x Unit Price. | C6: Formula (basic)
A7: 3 | B7: Using the Sales Rating Guide on the Product List sheet, create a Sales Rating for every order (Low, Medium, High, or Excellent) based on its Total Sales. | C7: IFS
A8: 4 | B8: Find the total sales value (N) for all orders from the Lagos region. | C8: SUMIF
A9: 5 | B9: Find the total number of units sold by the salesperson 'Tunde Bakare'. | C9: SUMIF
A10: 6 | B10: Count how many orders were paid for using 'Transfer'. | C10: COUNTIF
A11: 7 | B11: Find the total sales value (N) for orders from the Abuja region that were paid for with 'Card'. | C11: SUMIFS
A12: 8 | B12: Count how many orders were from 'New' customers in the Kano region. | C12: COUNTIFS
A13: 9 | B13: In a new column, use the AND function to flag (TRUE/FALSE) orders where the Region is 'Lagos' AND the Customer Type is 'Returning'. | C13: AND
A14: 10 | B14: In 2-3 sentences, summarise which region generated the most sales and which salesperson performed best, based on the formulas you built above. | C14: Data Analysis (open-ended)

Sheet Pivot Table
A3: Sum of Total Sales (N) | D3: Count of Order ID | F3: Sum of Units Sold | H3: Row Labels | I3: Sum of Total Sales (N)
A4: 65304500 | D4: 60 | F4: 1775 | H4: Abuja | I4: 20835000 | L4: Row Labels | M4: Sum of Total Sales (N)
H5: Ibadan | I5: 18394000 | L5: Femi Alabi | M5: 15862000
H6: Kano | I6: 12123500 | L6: Ibrahim Musa | M6: 13624500
H7: Lagos | I7: 10016000 | L7: Adaeze Obi | M7: 9253000
H8: Port Harcourt | I8: 3936000 | L8: Kemi Adisa | M8: 6522500
A9: Row Labels | B9: Sum of Units Sold | D9: Row Labels | E9: Sum of Total Sales (N) | H9: Grand Total | I9: 65304500 | L9: Sadiq Bello | M9: 6144000
A10: Abuja | B10: 633 | D10: 46027 | E10: 2142000 | L10: Tunde Bakare | M10: 6021500
A11: Ibadan | B11: 401 | D11: 46028 | E11: 1744000 | L11: Ngozi Umeh | M11: 4252000
A12: Kano | B12: 347 | D12: 46030 | E12: 450500 | L12: Chinwe Eze | M12: 3625000
A13: Lagos | B13: 244 | D13: 46032 | E13: 3472000 | H13: Row Labels | I13: Sum of Total Sales (N) | L13: Grand Total | M13: 65304500
A14: Port Harcourt | B14: 150 | D14: 46033 | E14: 408000 | H14: Cooking Essentials | I14: 19842000
A15: Grand Total | B15: 1775 | D15: 46034 | E15: 340000 | H15: Dairy | I15: 4384000
D16: 46035 | E16: 2570500 | H16: Grains | I16: 34631000
D17: 46037 | E17: 1558000 | H17: Household | I17: 3110000
D18: 46038 | E18: 136000 | H18: Packaged Foods | I18: 3337500
A19: Row Labels | B19: Sum of Total Sales (N) | D19: 46039 | E19: 714000 | H19: Grand Total | I19: 65304500
A20: Beans (50kg bag) | B20: 19530000 | D20: 46040 | E20: 1522000
A21: Vegetable Oil (25L) | B21: 9495000 | D21: 46045 | E21: 2842000
A22: Rice (50kg bag) | B22: 8500000 | D22: 46047 | E22: 1964000
A23: Granulated Sugar (50kg) | B23: 8120000 | D23: 46048 | E23: 340500
A24: Wheat Flour (50kg) | B24: 6601000 | D24: 46053 | E24: 1088000
A25: Powdered Milk (Carton) | B25: 4384000 | D25: 46056 | E25: 2887500
A26: Instant Noodles (Carton) | B26: 3337500 | D26: 46057 | E26: 108500
A27: Laundry Detergent (Carton) | B27: 2583000 | D27: 46058 | E27: 4101000
A28: Table Salt (Carton) | B28: 2227000 | D28: 46060 | E28: 1412000
A29: Bathing Soap (Carton) | B29: 527000 | D29: 46061 | E29: 1620000
A30: Grand Total | B30: 65304500 | D30: 46062 | E30: 1860000
D31: 46063 | E31: 137500
D32: 46065 | E32: 2050000
D33: 46066 | E33: 737500
D34: 46067 | E34: 493000
D35: 46072 | E35: 1488000
D36: 46074 | E36: 687500
D37: 46075 | E37: 492000
D38: 46080 | E38: 294500
D39: 46086 | E39: 336000
D40: 46089 | E40: 2160000
D41: 46091 | E41: 2378000
D42: 46092 | E42: 3876000
...
